<robot name = "robot">
    <link name="Link0">
        <inertial>
            <origin xyz="0 0 2" rpy="0 0 0"/>
            <mass value="1" />
            <inertia ixx="100" ixy="0" ixz="0" iyy="100" iyz="0" izz="100" />
        </inertial>
        <visual>
            <origin xyz="0 0 2" rpy="0 0 0"/>
            <geometry>
                <box size="1 1 2" />
            </geometry>
            <material name="Blue">
                <color rgba="0 0 1 1.0"/>
            </material>
        </visual>
        <collision>
            <origin xyz="0 0 2" rpy="0 0 0"/>
            <geometry>
                <box size="1 1 2" />
            </geometry>
        </collision>
    </link>
    <joint name="Link0_Link1" type="revolute">
       <parent link="Link0"/>
       <child  link="Link1"/>
       <origin rpy="0 0 0" xyz="0.5 0 1.0" />
     <axis xyz="1 0 0"/>
       <limit effort="0.0" lower="-3.14159" upper="3.14159" velocity="0.0"/>
    </joint>
    <link name="Link1">
        <inertial>
            <origin xyz="0 1.1299181043017898 0" rpy="0 0 0"/>
            <mass value="1" />
            <inertia ixx="100" ixy="0" ixz="0" iyy="100" iyz="0" izz="100" />
        </inertial>
        <visual>
            <origin xyz="0 1.1299181043017898 0" rpy="0 0 0"/>
            <geometry>
                <box size="2.2884035930674353 1.25983620860358 1.8279627087434456" />
            </geometry>
            <material name="Green">
                <color rgba="0 1 0 1.0"/>
            </material>
        </visual>
        <collision>
            <origin xyz="0 1.1299181043017898 0" rpy="0 0 0"/>
            <geometry>
                <box size="2.2884035930674353 1.25983620860358 1.8279627087434456" />
            </geometry>
        </collision>
    </link>
    <joint name="Link1_Link2" type="revolute">
       <parent link="Link1"/>
       <child  link="Link2"/>
       <origin rpy="0 0 0" xyz="0.6442017965337177 1.1299181043017898 0" />
     <axis xyz="0 1 0"/>
       <limit effort="0.0" lower="-3.14159" upper="3.14159" velocity="0.0"/>
    </joint>
    <link name="Link2">
        <inertial>
            <origin xyz="0 0 1.7192771005728273" rpy="0 0 0"/>
            <mass value="1" />
            <inertia ixx="100" ixy="0" ixz="0" iyy="100" iyz="0" izz="100" />
        </inertial>
        <visual>
            <origin xyz="0 0 1.7192771005728273" rpy="0 0 0"/>
            <geometry>
                <box size="2.5483132639448005 1.6727222072932015 1.6105914924022091" />
            </geometry>
            <material name="Green">
                <color rgba="0 1 0 1.0"/>
            </material>
        </visual>
        <collision>
            <origin xyz="0 0 1.7192771005728273" rpy="0 0 0"/>
            <geometry>
                <box size="2.5483132639448005 1.6727222072932015 1.6105914924022091" />
            </geometry>
        </collision>
    </link>
</robot>